Workbook

Sheet Inventory
A1: AI System Inventory
A2: Blended inventory: entries adapted and de-identified from an institutional AI service inventory together with additional synthetic entries created for this project. The two are not distinguished. Unit names are generalised, descriptions are written at use-case level, and compliance attestations, review dates, stewardship and data-quality tags are illustrative. No institution, customer or individual is identified.
A4: SYS_ID | B4: System_Name | C4: System_Purpose | D4: Data_Inputs | E4: Automated_Decision | F4: Personal_Data | G4: Risk_Level | H4: Business_Owner | I4: Technical_Owner | J4: Data_Steward | K4: Steward_Status | L4: Deployment_Env | M4: Last_Audit_Date | N4: Lineage_Status | O4: DQ_Regime | P4: Impact_Assessment | Q4: Human_Oversight | R4: Verification_Validation | S4: Technical_Doc | T4: Event_Logging | U4: Incident_Plan | V4: User_Transparency | W4: Intended_Use_Doc
A5: SYS-001 | B5: Card Transaction Fraud Scoring | C5: Real-time fraud likelihood scoring for card transactions; the score is consumed as a parameter by the fraud decision module | D5: DS-TXN-CARD; DS-CUST-MASTER; DS-DWH | E5: Y | F5: Y | G5: High | H5: Payment Systems Operations - Fraud Service | I5: AI Solutions - Fraud Analytics | J5: Payments Data Steward | K5: assigned | L5: On-Prem | M5: 46191 | N5: complete | O5: present | P5: Y | Q5: human-in-the-loop | R5: Y | S5: Y | T5: Y | U5: Y | V5: Y | W5: Y
A6: SYS-002 | B6: ATM Withdrawal Fraud Scoring | C6: Real-time fraud likelihood scoring for ATM cash-withdrawal transactions | D6: DS-TXN-ATM; DS-CUST-MASTER; DS-DWH | E6: Y | F6: Y | G6: High | H6: Payment Systems Operations - Fraud Service | I6: AI Solutions - Fraud Analytics | J6: Payments Data Steward | K6: assigned | L6: On-Prem | M6: 46172 | N6: complete | O6: present | P6: Y | Q6: human-in-the-loop | R6: Y | S6: Y | T6: Y | U6: Y | V6: Y | W6: Y
A7: SYS-003 | B7: Digital Channel Transfer Fraud Scoring | C7: Real-time fraud scoring of transfer and EFT transactions initiated through internet and mobile banking | D7: DS-TXN-EFT; DS-CUST-MASTER; DS-DWH | E7: Y | F7: Y | G7: High | H7: Payment Systems Operations - Fraud Service | I7: AI Solutions - Fraud Analytics | J7: Payments Data Steward | K7: assigned | L7: On-Prem | M7: 46134 | N7: complete | O7: present | P7: Y | Q7: human-in-the-loop | R7: Y | S7: Y | T7: Y | U7: Y | V7: N | W7: Y
A8: SYS-004 | B8: Retail Credit Scoring Engine | C8: Scores retail and SME financing applications to support approval decisions | D8: DS-CUST-MASTER; DS-CREDIT-BUREAU; DS-DWH | E8: Y | F8: Y | G8: High | H8: Retail Banking Directorate | I8: AI Solutions - Predictive Analytics | J8: Retail Data Steward | K8: assigned | L8: On-Prem | M8: 46178 | N8: complete | O8: present | P8: Y | Q8: human-in-the-loop | R8: Y | S8: Y | T8: Y | U8: Y | V8: Y | W8: Y
A9: SYS-005 | B9: Credit Card Limit Prediction | C9: Predicts credit card limits for salaried customers from financial behaviour and income indicators | D9: DS-CUST-MASTER; DS-PAYROLL; DS-CREDIT-BUREAU | E9: Y | F9: Y | G9: High | H9: Retail and Micro Loans Directorate | I9: AI Solutions - Predictive Analytics | J9: Retail Data Steward | K9: assigned | L9: On-Prem | M9: 46175 | N9: complete | O9: present | P9: Y | Q9: human-in-the-loop | R9: Y | S9: Y | T9: Y | U9: Y | V9: N | W9: Y
A10: SYS-006 | B10: AML Transaction Monitoring | C10: Flags potentially suspicious transaction patterns for analyst review under the AML programme | D10: DS-TXN-CARD; DS-TXN-EFT; DS-CUST-MASTER; DS-SANCTIONS | E10: N | F10: Y | G10: High | H10: Regulatory Compliance - AML | I10: AI Solutions - Fraud Analytics | J10: Compliance Data Steward | K10: assigned | L10: On-Prem | M10: 46156 | N10: complete | O10: present | P10: Y | Q10: human-on-the-loop | R10: Y | S10: Y | T10: Y | U10: Y | V10: N | W10: Y
A11: SYS-007 | B11: Cross-Region ATM Anomaly Detection | C11: Detects repeated withdrawals across distant regions under a single identity and refers cases to compliance | D11: DS-TXN-ATM; DS-CUST-MASTER | E11: N | F11: Y | G11: High | H11: Regulatory Compliance - AML | I11: AI Solutions - Fraud Analytics | J11: Compliance Data Steward | K11: assigned | L11: On-Prem | M11: 46108 | N11: partial | O11: present | P11: Y | Q11: human-on-the-loop | R11: Y | S11: N | T11: Y | U11: Y | V11: N | W11: Y
A12: SYS-008 | B12: Individual Collections Prediction | C12: Predicts which overdue individual customers will remain unpaid for 30 days; batch scores feed the collections module | D12: DS-COLLECTION-LOG; DS-CUST-MASTER; DS-DWH | E12: N | F12: Y | G12: High | H12: Collections Directorate | I12: AI Solutions - Predictive Analytics | J12: (collections lead) | K12: de_facto | L12: On-Prem | M12: 46063 | N12: partial | O12: present | P12: Y | Q12: human-on-the-loop | R12: Y | S12: Y | T12: N | U12: Y | V12: N | W12: Y
A13: SYS-009 | B13: Loan Default Early Warning | C13: Advisory risk scoring across the existing loan book to flag deteriorating exposures | D13: DS-DWH; DS-CREDIT-BUREAU; DS-MACRO-FEED | E13: N | F13: Y | G13: High | H13: Risk Management Directorate | I13: AI Solutions - Predictive Analytics | J13: Risk Data Steward | K13: assigned | L13: On-Prem | M13: 46163 | N13: complete | O13: present | P13: Y | Q13: human-on-the-loop | R13: Y | S13: Y | T13: N | U13: Y | V13: N | W13: Y
A14: SYS-010 | B14: Identity Photo Watchlist Similarity | C14: Compares a new customer identity photo against watchlisted identity photos and returns a distance score | D14: DS-DOC-ID; DS-WATCHLIST-PHOTO | E14: N | F14: Y | G14: High | H14: Data Governance Service | I14: AI Solutions - Computer Vision | J14: Data Governance Steward | K14: assigned | L14: On-Prem | M14: 46095 | N14: partial | O14: present | P14: Y | Q14: human-in-the-loop | R14: Y | S14: N | T14: N | U14: Y | V14: N | W14: Y
A15: SYS-011 | B15: Sensitive Field Redaction on ID Documents | C15: Redacts religion and blood-group fields (special-category data) on identity and driving-licence images | D15: DS-DOC-ID | E15: N | F15: Y | G15: High | H15: Data Governance Service | I15: AI Solutions - Computer Vision | J15: Data Governance Steward | K15: assigned | L15: On-Prem | M15: 46150 | N15: complete | O15: present | P15: Y | Q15: human-on-the-loop | R15: Y | S15: Y | T15: N | U15: Y | V15: N | W15: Y
A16: SYS-012 | B16: Customer Churn Prediction | C16: Monthly churn propensity score for all customers, written to the data warehouse for downstream use | D16: DS-DWH-MARKETING; DS-CUST-MASTER | E16: N | F16: Y | G16: Medium | H16: Marketing - CRM Service | I16: AI Solutions - Predictive Analytics | J16: (CRM analyst lead) | K16: de_facto | L16: On-Prem | M16: 46042 | N16: partial | O16: present | P16: N | R16: Y | S16: N | T16: N | U16: N | V16: N | W16: Y
A17: SYS-013 | B17: Product Propensity Models | C17: Monthly propensity scores for product take-up and attrition across retail, micro and corporate products | D17: DS-DWH-MARKETING; DS-CUST-MASTER | E17: N | F17: Y | G17: Medium | H17: Marketing - CRM Service | I17: AI Solutions - Predictive Analytics | J17: (unassigned) | K17: unassigned | L17: On-Prem | M17: 45973 | N17: partial | O17: absent | P17: N | R17: N | S17: N | T17: N | U17: N | V17: N | W17: N
A18: SYS-014 | B18: Behavioural Customer Segmentation | C18: Segments retail and corporate customers by product, channel and asset behaviour; monthly batch service | D18: DS-DWH-MARKETING; DS-CUST-MASTER | E18: N | F18: Y | G18: Medium | H18: Digital Marketing and Sales | I18: AI Solutions - Predictive Analytics | J18: (unassigned) | K18: unassigned | L18: On-Prem | M18: 45994 | N18: partial | O18: absent | P18: N | R18: N | S18: N | T18: N | U18: N | V18: N | W18: N
A19: SYS-015 | B19: Marketing Campaign Optimiser | C19: Selects target segments and channels for outbound campaigns automatically | D19: DS-DWH-MARKETING; DS-CAMPAIGN-HIST | E19: Y | F19: Y | G19: Medium | H19: Digital Marketing and Sales | I19: AI Solutions - Predictive Analytics | J19: (unassigned) | K19: unassigned | L19: On-Prem | M19: 46071 | N19: partial | O19: absent | P19: N | Q19: none | R19: N | S19: N | T19: N | U19: N | V19: N | W19: N
A20: SYS-016 | B20: Survey Free-Text Categorisation | C20: Classifies open-ended customer survey responses into six experience categories; daily batch | D20: DS-SURVEY-TEXT | E20: N | F20: Y | G20: Low | H20: Marketing - CRM Service | I20: AI Solutions - NLP | J20: (CRM analyst lead) | K20: de_facto | L20: On-Prem | M20: 46111 | N20: complete | O20: present | P20: N | R20: Y | S20: Y | T20: N | U20: Y | V20: N | W20: Y
A21: SYS-017 | B21: Automated Complaint Categorisation | C21: Classifies incoming complaint texts by topic and routes them to the responsible unit in real time | D21: DS-COMPLAINT-TEXT | E21: Y | F21: Y | G21: Medium | H21: Payment Systems Operations - Customer Experience | I21: AI Solutions - NLP | J21: Customer Experience Steward | K21: assigned | L21: On-Prem | M21: 46123 | N21: complete | O21: present | P21: Y | Q21: human-on-the-loop | R21: Y | S21: Y | T21: Y | U21: Y | V21: N | W21: Y
A22: SYS-018 | B22: Call Centre Speech Analytics | C22: Sentiment and compliance-keyword detection over recorded customer calls | D22: DS-CALL-REC; DS-CUST-MASTER | E22: N | F22: Y | G22: Medium | H22: Payment Systems Operations - Customer Experience | I22: AI Solutions - NLP | J22: (unassigned) | K22: unassigned | L22: On-Prem | M22: 45996 | N22: absent | O22: absent | P22: N | R22: N | S22: N | T22: N | U22: N | V22: N | W22: N
A23: SYS-019 | B23: Multilingual Virtual Assistant | C23: Question-answering assistant for the mobile app and topic-specific channels in Turkish, English and Arabic | D23: DS-FAQ-KB; DS-CUST-MASTER | E23: N | F23: Y | G23: Medium | H23: R&D Directorate | I23: AI Solutions - Conversational AI | J23: (R&D lead) | K23: de_facto | L23: On-Prem | M23: 46120 | N23: partial | O23: present | P23: Y | Q23: human-on-the-loop | R23: Y | S23: Y | T23: N | U23: Y | V23: Y | W23: Y
A24: SYS-020 | B24: Cheque Signature Presence Detection | C24: Detects the presence or absence of drawer signatures on cheque images | D24: DS-DOC-CHEQUE | E24: N | F24: Y | G24: Medium | H24: Banking Services Operations | I24: AI Solutions - Computer Vision | J24: Banking Ops Steward | K24: assigned | L24: On-Prem | M24: 46079 | N24: complete | O24: present | P24: Y | Q24: human-in-the-loop | R24: Y | S24: Y | T24: N | U24: Y | V24: N | W24: Y
A25: SYS-021 | B25: Signature Verification Against Circulars | C25: Matches each signature on an instruction document to the customer signature circular and returns similarity scores | D25: DS-DOC-INSTRUCTION; DS-SIGNATURE-CIRCULAR | E25: N | F25: Y | G25: High | H25: Banking Services Operations | I25: AI Solutions - Computer Vision | J25: Banking Ops Steward | K25: assigned | L25: On-Prem | M25: 46161 | N25: complete | O25: present | P25: Y | Q25: human-in-the-loop | R25: Y | S25: Y | T25: Y | U25: Y | V25: N | W25: Y
A26: SYS-022 | B26: Identity Document Entity Extraction | C26: Extracts requested fields from four identity document types using detection and OCR | D26: DS-DOC-ID | E26: N | F26: Y | G26: Medium | H26: Banking Services Operations | I26: AI Solutions - Computer Vision | J26: Banking Ops Steward | K26: assigned | L26: On-Prem | M26: 46182 | N26: complete | O26: present | P26: Y | Q26: human-on-the-loop | R26: Y | S26: Y | T26: Y | U26: Y | V26: Y | W26: Y
A27: SYS-023 | B27: Cheque Entity Extraction | C27: Extracts amount, currency and party fields from local and foreign-currency cheques via detection and OCR | D27: DS-DOC-CHEQUE | E27: N | F27: Y | G27: Medium | H27: Banking Services Operations | I27: AI Solutions - Computer Vision | J27: Banking Ops Steward | K27: assigned | L27: On-Prem | M27: 46129 | N27: complete | O27: present | P27: Y | Q27: human-on-the-loop | R27: Y | S27: Y | T27: Y | U27: Y | V27: N | W27: Y
A28: SYS-024 | B28: Trade Finance Document Entity Extraction | C28: Extracts invoice, bank and SWIFT fields from import, letter-of-credit and fund-transfer request forms | D28: DS-DOC-TRADE | E28: N | F28: N | G28: Medium | H28: Trade Finance Operations | I28: AI Solutions - Computer Vision | J28: (trade ops lead) | K28: de_facto | L28: On-Prem | M28: 46086 | N28: partial | O28: present | P28: N | R28: Y | S28: N | T28: N | U28: Y | V28: N | W28: Y
A29: SYS-025 | B29: Registered E-Mail Document Classification | C29: Classifies registered e-mail (KEP) documents into legal action categories and extracts requested fields | D29: DS-DOC-KEP | E29: N | F29: Y | G29: Medium | H29: Banking Services Operations | I29: AI Solutions - NLP | J29: (unassigned) | K29: unassigned | L29: On-Prem | M29: 45924 | N29: absent | O29: absent | P29: N | R29: N | S29: N | T29: N | U29: N | V29: N | W29: N
A30: SYS-026 | B30: Mortgage Document Entity Extraction | C30: Extracts entry number and date fields from real-estate mortgage documents | D30: DS-MORTGAGE-DOC | E30: N | F30: Y | G30: Medium | H30: Credit Operations and Collateral Management | I30: AI Solutions - Computer Vision | J30: (credit ops lead) | K30: de_facto | L30: On-Prem | M30: 46142 | N30: partial | O30: present | P30: Y | Q30: human-on-the-loop | R30: Y | S30: Y | T30: N | U30: Y | V30: N | W30: Y
A31: SYS-027 | B31: Financial Statement PDF Digitisation | C31: Converts PDF trial balances and financial statements into structured spreadsheets for credit assessment | D31: DS-DOC-FINSTMT | E31: N | F31: N | G31: Medium | H31: Commercial Loans Directorate | I31: AI Solutions - Computer Vision | J31: (commercial loans lead) | K31: de_facto | L31: On-Prem | M31: 46057 | N31: partial | O31: present | P31: N | R31: Y | S31: N | T31: N | U31: Y | V31: N | W31: Y
A32: SYS-028 | B32: Contract Text Template Matching | C32: Matches customer-supplied special text requests to registered contract templates using nightly-refreshed embeddings | D32: DS-TEXT-TEMPLATE; DS-DOC-INSTRUCTION | E32: N | F32: Y | G32: Medium | H32: Credit Operations and Collateral Management | I32: AI Solutions - NLP | J32: (credit ops lead) | K32: de_facto | L32: On-Prem | M32: 46168 | N32: partial | O32: present | P32: N | R32: Y | S32: Y | T32: N | U32: Y | V32: N | W32: Y
A33: SYS-029 | B33: Commercial Financing Pricing Model | C33: Regression model estimating cash financing prices, used on the commercial pricing screens | D33: DS-PRICING-HIST; DS-DWH | E33: N | F33: N | G33: Medium | H33: Pricing Service | I33: AI Solutions - Predictive Analytics | J33: Pricing Data Steward | K33: assigned | L33: On-Prem | M33: 46185 | N33: complete | O33: present | P33: Y | Q33: human-in-the-loop | R33: Y | S33: Y | T33: N | U33: Y | V33: N | W33: Y
A34: SYS-030 | B34: Guarantee Letter Pricing Model | C34: Regression model estimating guarantee-letter commission rates, used on the guarantee pricing screens | D34: DS-PRICING-HIST; DS-DWH | E34: N | F34: N | G34: Medium | H34: Pricing Service | I34: AI Solutions - Predictive Analytics | J34: Pricing Data Steward | K34: assigned | L34: On-Prem | M34: 45960 | N34: partial | O34: present | P34: N | R34: N | S34: N | T34: N | U34: N | V34: N | W34: N
A35: SYS-031 | B35: Corporate Media Intelligence Screening | C35: Scans local and national news, identifies corporate entities and classifies articles for intelligence reporting | D35: DS-NEWS-FEED; DS-CUST-MASTER | E35: N | F35: Y | G35: Medium | H35: Corporate Intelligence Directorate | I35: AI Solutions - NLP | J35: (intelligence lead) | K35: de_facto | L35: On-Prem | M35: 46030 | N35: partial | O35: absent | P35: N | R35: Y | S35: N | T35: N | U35: N | V35: N | W35: Y
A36: SYS-032 | B36: QR and DataMatrix Code Reading Service | C36: Detects and reads QR and DataMatrix codes embedded in documents; integration-ready shared service | D36: DS-DOC-SHARED | E36: N | F36: N | G36: Low | H36: Business Excellence and Innovation | I36: AI Solutions - Computer Vision | J36: Platform Steward | K36: assigned | L36: On-Prem | M36: 46144 | N36: complete | O36: present | P36: N | R36: Y | S36: Y | T36: N | U36: Y | V36: N | W36: Y
A37: SYS-033 | B37: On-Premises OCR Platform Service | C37: Shared containerised OCR service providing document text extraction to other AI systems | D37: DS-DOC-SHARED | E37: N | F37: N | G37: Low | H37: Business Excellence and Innovation | I37: AI Solutions - Platform | J37: Platform Steward | K37: assigned | L37: On-Prem | M37: 46198 | N37: complete | O37: present | P37: N | R37: Y | S37: Y | T37: Y | U37: Y | V37: Y | W37: Y
A38: SYS-034 | B38: Branch Cash Demand Forecast | C38: Forecasts ATM and branch cash replenishment requirements | D38: DS-CASH-LOG; DS-CALENDAR; DS-MACRO-FEED | E38: N | F38: N | G38: Low | H38: Branch Operations | I38: AI Solutions - Predictive Analytics | J38: (ops planning lead) | K38: de_facto | L38: On-Prem | M38: 46103 | N38: complete | O38: present | P38: N | R38: Y | S38: Y | T38: N | U38: Y | V38: N | W38: Y
A39: SYS-035 | B39: CV Screening Support | C39: Ranks job applicants against role requirements to support recruitment shortlisting | D39: DS-HR-APPLICANT | E39: Y | F39: Y | G39: High | H39: Human Resources Directorate | I39: AI Solutions - Predictive Analytics | J39: (unassigned) | K39: unassigned | L39: On-Prem | M39: 45884 | N39: absent | O39: absent | P39: N | Q39: none | R39: N | S39: N | T39: N | U39: N | V39: N | W39: N
A40: SYS-036 | B40: Voice Biometrics Authentication | C40: Authenticates customers in the call centre and mobile channel from voiceprints; an accepted match completes authentication automatically | D40: DS-VOICEPRINT; DS-CALL-REC; DS-CUST-MASTER | E40: Y | F40: Y | G40: High | H40: Digital Channels Directorate | I40: AI Solutions - Platform | J40: Identity Data Steward | K40: assigned | L40: On-Prem | M40: 46187 | N40: complete | O40: present | P40: Y | Q40: human-in-the-loop | R40: Y | S40: Y | T40: Y | U40: Y | V40: N | W40: Y
A41: SYS-037 | B41: Robo-Advisory Portfolio Recommendation | C41: Generates investment portfolio recommendations from customer risk profile and holdings, presented directly to the customer | D41: DS-CUST-MASTER; DS-PORTFOLIO; DS-MARKET-FEED | E41: Y | F41: Y | G41: High | H41: Wealth Management Directorate | I41: AI Solutions - Predictive Analytics | J41: (unassigned) | K41: unassigned | L41: On-Prem | M41: 46009 | N41: partial | O41: absent | P41: N | Q41: none | R41: N | S41: N | T41: N | U41: N | V41: N | W41: N
...

Sheet Data_Sources
A1: Data Sources
A3: Source_ID | B3: Source_Name | C3: Source_Type | D3: Contains_Personal_Data | E3: DQ_Regime | F3: Source_Owner | G3: Notes
A4: DS-CUST-MASTER | B4: Customer Master | C4: Internal DB | D4: Y | E4: present | F4: Data Management and Analytics Directorate | G4: Golden customer record; KVKK personal data.
A5: DS-DWH | B5: Enterprise Data Warehouse | C5: Internal DB | D5: Y | E5: present | F5: Data Management and Analytics Directorate | G5: Shared analytical layer.
A6: DS-DWH-MARKETING | B6: Marketing Datamart | C6: Internal DB | D6: Y | E6: present | F6: Data Management and Analytics Directorate | G6: Marketing analytical datamart.
A7: DS-TXN-CARD | B7: Card Transaction Stream | C7: Streaming | D7: Y | E7: present | F7: Payment Systems Operations | G7: Real-time card authorisations.
A8: DS-TXN-ATM | B8: ATM Transaction Stream | C8: Streaming | D8: Y | E8: present | F8: Payment Systems Operations | G8: ATM withdrawal events.
A9: DS-TXN-EFT | B9: Transfer / EFT Stream | C9: Streaming | D9: Y | E9: present | F9: Payment Systems Operations | G9: Internet and mobile transfers.
A10: DS-SANCTIONS | B10: Sanctions and Watchlist Feed | C10: External API | D10: Y | E10: present | F10: Regulatory Compliance - AML | G10: Externally maintained lists.
A11: DS-COLLECTION-LOG | B11: Collections Activity Log | C11: Internal DB | D11: Y | E11: present | F11: Collections Directorate | G11: Overdue and contact records.
A12: DS-CREDIT-BUREAU | B12: Credit Bureau Feed | C12: External API | D12: Y | E12: present | F12: Retail and Micro Loans Directorate | G12: Third-party bureau data.
A13: DS-PAYROLL | B13: Payroll / Income Records | C13: Internal DB | D13: Y | E13: present | F13: Retail and Micro Loans Directorate | G13: Salary-customer income data.
A14: DS-MACRO-FEED | B14: Macroeconomic Indicators | C14: External API | D14: N | E14: present | F14: Risk Management Directorate | G14: Rates and indices.
... A42: DS-MODEL-TELEMETRY | B42: Model Telemetry Store | C42: Internal DB | D42: N | E42: present | F42: Data Management and Analytics Directorate | G42: Production model performance and drift metrics.

Sheet Lineage_Edges
A1: Structural Lineage Edge List (source -> system -> consumer)
A2: Systems with no documented consumer edge carry Lineage_Status = absent or partial.
A4: Edge_ID | B4: From_Node | C4: To_Node | D4: Edge_Type | E4: From_Type | F4: To_Type
A5: E001 | B5: DS-TXN-CARD | C5: SYS-001 | D5: feeds | E5: data_source | F5: ai_system
A6: E002 | B6: DS-CUST-MASTER | C6: SYS-001 | D6: feeds | E6: data_source | F6: ai_system
A7: E003 | B7: DS-DWH | C7: SYS-001 | D7: feeds | E7: data_source | F7: ai_system
A8: E004 | B8: DS-TXN-ATM | C8: SYS-002 | D8: feeds | E8: data_source | F8: ai_system
A9: E005 | B9: DS-CUST-MASTER | C9: SYS-002 | D9: feeds | E9: data_source | F9: ai_system
A10: E006 | B10: DS-DWH | C10: SYS-002 | D10: feeds | E10: data_source | F10: ai_system
A11: E007 | B11: DS-TXN-EFT | C11: SYS-003 | D11: feeds | E11: data_source | F11: ai_system
A12: E008 | B12: DS-CUST-MASTER | C12: SYS-003 | D12: feeds | E12: data_source | F12: ai_system
A13: E009 | B13: DS-DWH | C13: SYS-003 | D13: feeds | E13: data_source | F13: ai_system
A14: E010 | B14: DS-CUST-MASTER | C14: SYS-004 | D14: feeds | E14: data_source | F14: ai_system
A15: E011 | B15: DS-CREDIT-BUREAU | C15: SYS-004 | D15: feeds | E15: data_source | F15: ai_system
... A107: E103 | B107: SYS-038 | C107: CONS-038 | D107: consumed_by | E107: ai_system | F107: consumer

Sheet Gap_Summary
A1: Data-layer Gap Summary (live - recomputes from Inventory)
A2: Lineage / data-quality / stewardship / stale-audit findings. Control compliance is evaluated in the app.
A3: Reference date: | B3: 46263 | C3: Stale window (days): | D3: 180
A5: SYS_ID | B5: System_Name | C5: Risk_Level | D5: Lineage_Gap | E5: DQ_Gap | F5: Steward_Gap | G5: Stale_Audit | H5: Total_Gaps | I5: Priority
A6: =Inventory!A5 -> SYS-001 | B6: =Inventory!B5 -> Card Transaction Fraud Scoring | C6: =Inventory!G5 -> High | D6: =IF(Inventory!N5<>"complete","GAP","") | E6: =IF(Inventory!O5="absent","GAP","") | F6: =IF(Inventory!K5="unassigned","GAP","") | G6: =IF(($B$3-Inventory!M5)>$D$3,"STALE","") | H6: =COUNTIF(D6:G6,"GAP")+COUNTIF(D6:G6,"STALE") -> 0 | I6: =IF(AND(C6="High",H6>=2),"P1-Critical",IF(OR(C6="High",H6>=2),"P2-High",IF(H6>=1,"P3-Medium","P4-Low"))) -> P2-High
A7: =Inventory!A6 -> SYS-002 | B7: =Inventory!B6 -> ATM Withdrawal Fraud Scoring | C7: =Inventory!G6 -> High | D7: =IF(Inventory!N6<>"complete","GAP","") | E7: =IF(Inventory!O6="absent","GAP","") | F7: =IF(Inventory!K6="unassigned","GAP","") | G7: =IF(($B$3-Inventory!M6)>$D$3,"STALE","") | H7: =COUNTIF(D7:G7,"GAP")+COUNTIF(D7:G7,"STALE") -> 0 | I7: =IF(AND(C7="High",H7>=2),"P1-Critical",IF(OR(C7="High",H7>=2),"P2-High",IF(H7>=1,"P3-Medium","P4-Low"))) -> P2-High
A8: =Inventory!A7 -> SYS-003 | B8: =Inventory!B7 -> Digital Channel Transfer Fraud Scoring | C8: =Inventory!G7 -> High | D8: =IF(Inventory!N7<>"complete","GAP","") | E8: =IF(Inventory!O7="absent","GAP","") | F8: =IF(Inventory!K7="unassigned","GAP","") | G8: =IF(($B$3-Inventory!M7)>$D$3,"STALE","") | H8: =COUNTIF(D8:G8,"GAP")+COUNTIF(D8:G8,"STALE") -> 0 | I8: =IF(AND(C8="High",H8>=2),"P1-Critical",IF(OR(C8="High",H8>=2),"P2-High",IF(H8>=1,"P3-Medium","P4-Low"))) -> P2-High
A9: =Inventory!A8 -> SYS-004 | B9: =Inventory!B8 -> Retail Credit Scoring Engine | C9: =Inventory!G8 -> High | D9: =IF(Inventory!N8<>"complete","GAP","") | E9: =IF(Inventory!O8="absent","GAP","") | F9: =IF(Inventory!K8="unassigned","GAP","") | G9: =IF(($B$3-Inventory!M8)>$D$3,"STALE","") | H9: =COUNTIF(D9:G9,"GAP")+COUNTIF(D9:G9,"STALE") -> 0 | I9: =IF(AND(C9="High",H9>=2),"P1-Critical",IF(OR(C9="High",H9>=2),"P2-High",IF(H9>=1,"P3-Medium","P4-Low"))) -> P2-High
A10: =Inventory!A9 -> SYS-005 | B10: =Inventory!B9 -> Credit Card Limit Prediction | C10: =Inventory!G9 -> High | D10: =IF(Inventory!N9<>"complete","GAP","") | E10: =IF(Inventory!O9="absent","GAP","") | F10: =IF(Inventory!K9="unassigned","GAP","") | G10: =IF(($B$3-Inventory!M9)>$D$3,"STALE","") | H10: =COUNTIF(D10:G10,"GAP")+COUNTIF(D10:G10,"STALE") -> 0 | I10: =IF(AND(C10="High",H10>=2),"P1-Critical",IF(OR(C10="High",H10>=2),"P2-High",IF(H10>=1,"P3-Medium","P4-Low"))) -> P2-High
A11: =Inventory!A10 -> SYS-006 | B11: =Inventory!B10 -> AML Transaction Monitoring | C11: =Inventory!G10 -> High | D11: =IF(Inventory!N10<>"complete","GAP","") | E11: =IF(Inventory!O10="absent","GAP","") | F11: =IF(Inventory!K10="unassigned","GAP","") | G11: =IF(($B$3-Inventory!M10)>$D$3,"STALE","") | H11: =COUNTIF(D11:G11,"GAP")+COUNTIF(D11:G11,"STALE") -> 0 | I11: =IF(AND(C11="High",H11>=2),"P1-Critical",IF(OR(C11="High",H11>=2),"P2-High",IF(H11>=1,"P3-Medium","P4-Low"))) -> P2-High
A12: =Inventory!A11 -> SYS-007 | B12: =Inventory!B11 -> Cross-Region ATM Anomaly Detection | C12: =Inventory!G11 -> High | D12: =IF(Inventory!N11<>"complete","GAP","") -> GAP | E12: =IF(Inventory!O11="absent","GAP","") | F12: =IF(Inventory!K11="unassigned","GAP","") | G12: =IF(($B$3-Inventory!M11)>$D$3,"STALE","") | H12: =COUNTIF(D12:G12,"GAP")+COUNTIF(D12:G12,"STALE") -> 1 | I12: =IF(AND(C12="High",H12>=2),"P1-Critical",IF(OR(C12="High",H12>=2),"P2-High",IF(H12>=1,"P3-Medium","P4-Low"))) -> P2-High
A13: =Inventory!A12 -> SYS-008 | B13: =Inventory!B12 -> Individual Collections Prediction | C13: =Inventory!G12 -> High | D13: =IF(Inventory!N12<>"complete","GAP","") -> GAP | E13: =IF(Inventory!O12="absent","GAP","") | F13: =IF(Inventory!K12="unassigned","GAP","") | G13: =IF(($B$3-Inventory!M12)>$D$3,"STALE","") -> STALE | H13: =COUNTIF(D13:G13,"GAP")+COUNTIF(D13:G13,"STALE") -> 2 | I13: =IF(AND(C13="High",H13>=2),"P1-Critical",IF(OR(C13="High",H13>=2),"P2-High",IF(H13>=1,"P3-Medium","P4-Low"))) -> P1-Critical
A14: =Inventory!A13 -> SYS-009 | B14: =Inventory!B13 -> Loan Default Early Warning | C14: =Inventory!G13 -> High | D14: =IF(Inventory!N13<>"complete","GAP","") | E14: =IF(Inventory!O13="absent","GAP","") | F14: =IF(Inventory!K13="unassigned","GAP","") | G14: =IF(($B$3-Inventory!M13)>$D$3,"STALE","") | H14: =COUNTIF(D14:G14,"GAP")+COUNTIF(D14:G14,"STALE") -> 0 | I14: =IF(AND(C14="High",H14>=2),"P1-Critical",IF(OR(C14="High",H14>=2),"P2-High",IF(H14>=1,"P3-Medium","P4-Low"))) -> P2-High
A15: =Inventory!A14 -> SYS-010 | B15: =Inventory!B14 -> Identity Photo Watchlist Similarity | C15: =Inventory!G14 -> High | D15: =IF(Inventory!N14<>"complete","GAP","") -> GAP | E15: =IF(Inventory!O14="absent","GAP","") | F15: =IF(Inventory!K14="unassigned","GAP","") | G15: =IF(($B$3-Inventory!M14)>$D$3,"STALE","") | H15: =COUNTIF(D15:G15,"GAP")+COUNTIF(D15:G15,"STALE") -> 1 | I15: =IF(AND(C15="High",H15>=2),"P1-Critical",IF(OR(C15="High",H15>=2),"P2-High",IF(H15>=1,"P3-Medium","P4-Low"))) -> P2-High
A16: =Inventory!A15 -> SYS-011 | B16: =Inventory!B15 -> Sensitive Field Redaction on ID Documents | C16: =Inventory!G15 -> High | D16: =IF(Inventory!N15<>"complete","GAP","") | E16: =IF(Inventory!O15="absent","GAP","") | F16: =IF(Inventory!K15="unassigned","GAP","") | G16: =IF(($B$3-Inventory!M15)>$D$3,"STALE","") | H16: =COUNTIF(D16:G16,"GAP")+COUNTIF(D16:G16,"STALE") -> 0 | I16: =IF(AND(C16="High",H16>=2),"P1-Critical",IF(OR(C16="High",H16>=2),"P2-High",IF(H16>=1,"P3-Medium","P4-Low"))) -> P2-High
A17: =Inventory!A16 -> SYS-012 | B17: =Inventory!B16 -> Customer Churn Prediction | C17: =Inventory!G16 -> Medium | D17: =IF(Inventory!N16<>"complete","GAP","") -> GAP | E17: =IF(Inventory!O16="absent","GAP","") | F17: =IF(Inventory!K16="unassigned","GAP","") | G17: =IF(($B$3-Inventory!M16)>$D$3,"STALE","") -> STALE | H17: =COUNTIF(D17:G17,"GAP")+COUNTIF(D17:G17,"STALE") -> 2 | I17: =IF(AND(C17="High",H17>=2),"P1-Critical",IF(OR(C17="High",H17>=2),"P2-High",IF(H17>=1,"P3-Medium","P4-Low"))) -> P2-High
... A49: =Inventory!A48 -> SYS-044 | B49: =Inventory!B48 -> Synthetic Data Generation Service | C49: =Inventory!G48 -> High | D49: =IF(Inventory!N48<>"complete","GAP","") -> GAP | E49: =IF(Inventory!O48="absent","GAP","") | F49: =IF(Inventory!K48="unassigned","GAP","") -> GAP | G49: =IF(($B$3-Inventory!M48)>$D$3,"STALE","") -> STALE | H49: =COUNTIF(D49:G49,"GAP")+COUNTIF(D49:G49,"STALE") -> 3 | I49: =IF(AND(C49="High",H49>=2),"P1-Critical",IF(OR(C49="High",H49>=2),"P2-High",IF(H49>=1,"P3-Medium","P4-Low"))) -> P1-Critical
A51: Portfolio summary
A52: Systems | B52: =COUNTA(A6:A49) -> 44
A53: P1-Critical | B53: =COUNTIF(I6:I49,"P1-Critical") -> 4
A54: Systems with >=1 gap | B54: =COUNTIF(H6:H49,">=1") -> 22
A55: Lineage gaps | B55: =COUNTIF(D6:D49,"GAP") -> 21
A56: DQ gaps | B56: =COUNTIF(E6:E49,"GAP") -> 9
A57: Stewardship gaps | B57: =COUNTIF(F6:F49,"GAP") -> 9
A58: Stale audits | B58: =COUNTIF(G6:G49,"STALE") -> 15

Sheet Data_Dictionary
A1: Data Dictionary & Tag Vocabulary
A3: Sheet / Field | B3: Meaning | C3: Allowed values
A4: Inventory.SYS_ID | B4: Unique system identifier; key for RAG corpus indexing (Layer 5). | C4: SYS-NNN
A5: Inventory.Data_Inputs | B5: Named source IDs feeding the system; basis of structural lineage. | C5: Semicolon list of DS-* IDs
A6: Inventory.Automated_Decision | B6: Whether the system makes or materially drives automated decisions. | C6: Y / N
A7: Inventory.Personal_Data | B7: Whether personal data (KVKK/GDPR) is processed. | C7: Y / N
A8: Inventory.Risk_Level | B8: Assessed risk level; drives monitoring depth. | C8: Low / Medium / High
A9: Inventory.Business_Owner | B9: Accountable business unit. | C9: Unit name
A10: Inventory.Technical_Owner | B10: Accountable technical team (AI Solutions Directorate). | C10: Team name
A11: Inventory.Steward_Status | B11: DAMA Data Governance tag: is a data steward formally assigned? (A.3.2) | C11: assigned / de_facto / unassigned
A12: Inventory.Lineage_Status | B12: DAMA Metadata Management tag: documented lineage completeness (A.7.5). | C12: complete / partial / absent
A13: Inventory.DQ_Regime | B13: DAMA Data Quality tag: data-quality regime for the system's inputs (A.7.4). | C13: present / absent
A14: Inventory.Last_Audit_Date | B14: Date of most recent review; feeds the stale-audit test (A.6.2.6). | C14: ISO 8601 date
... A24: Scope note | B24: Scheduled SQL reports and rule-based extracts that involve no AI technique are excluded from this inventory and should be scoped out of the AIMS by formal decision. | C24: -
